[2023-11-24 18:40:01] [error] [C:\Users\Lenovo\PycharmProjects\pythonProject\LSTM_prediction.py - 69 - <module>] 读取数据失败, 失败原因为
[2023-11-24 18:40:01] [error] [C:\Users\Lenovo\PycharmProjects\pythonProject\LSTM_prediction.py - 70 - <module>] Traceback (most recent call last):
  File "C:\Users\Lenovo\PycharmProjects\pythonProject\LSTM_prediction.py", line 67, in <module>
    data = pd.read_csv(filepath, encoding="gbk")  # 读取 CSV 格式的数据文件
  File "E:\conda\envs\pytorch\lib\site-packages\pandas\io\parsers\readers.py", line 912, in read_csv
    return _read(filepath_or_buffer, kwds)
  File "E:\conda\envs\pytorch\lib\site-packages\pandas\io\parsers\readers.py", line 577, in _read
    parser = TextFileReader(filepath_or_buffer, **kwds)
  File "E:\conda\envs\pytorch\lib\site-packages\pandas\io\parsers\readers.py", line 1407, in __init__
    self._engine = self._make_engine(f, self.engine)
  File "E:\conda\envs\pytorch\lib\site-packages\pandas\io\parsers\readers.py", line 1661, in _make_engine
    self.handles = get_handle(
  File "E:\conda\envs\pytorch\lib\site-packages\pandas\io\common.py", line 859, in get_handle
    handle = open(
FileNotFoundError: [Errno 2] No such file or directory: './data/pv\\PV_traintime.csv'

