[2023-11-29 21:54:20] [error] [C:\Users\Lenovo\PycharmProjects\光伏功率预测\predict_main.py - 82 - <module>] Traceback (most recent call last):
  File "E:\conda\envs\pytorch\lib\site-packages\mysql\connector\connection_cext.py", line 639, in cmd_query
    self._cmysql.query(
_mysql_connector.MySQLInterfaceError: Unknown column 'forcast_time' in 'field list'

The above exception was the direct cause of the following exception:

Traceback (most recent call last):
  File "C:\Users\Lenovo\PycharmProjects\光伏功率预测\predict_main.py", line 79, in <module>
    InsertData(table_name='sheet3', data_dict=data_dict)
  File "C:\Users\Lenovo\PycharmProjects\光伏功率预测\sql_lstm.py", line 118, in InsertData
    cursor.execute(sql, data)
  File "E:\conda\envs\pytorch\lib\site-packages\mysql\connector\cursor_cext.py", line 330, in execute
    result = self._cnx.cmd_query(
  File "E:\conda\envs\pytorch\lib\site-packages\mysql\connector\opentelemetry\context_propagation.py", line 77, in wrapper
    return method(cnx, *args, **kwargs)
  File "E:\conda\envs\pytorch\lib\site-packages\mysql\connector\connection_cext.py", line 647, in cmd_query
    raise get_mysql_exception(
mysql.connector.errors.ProgrammingError: 1054 (42S22): Unknown column 'forcast_time' in 'field list'

[2023-11-29 21:58:14] [error] [C:\Users\Lenovo\PycharmProjects\光伏功率预测\predict_main.py - 81 - <module>] 插入数据失败, 失败原因为
[2023-11-29 21:58:14] [error] [C:\Users\Lenovo\PycharmProjects\光伏功率预测\predict_main.py - 82 - <module>] Traceback (most recent call last):
  File "E:\conda\envs\pytorch\lib\site-packages\mysql\connector\connection_cext.py", line 639, in cmd_query
    self._cmysql.query(
_mysql_connector.MySQLInterfaceError: Unknown column 'forcast_time' in 'field list'

The above exception was the direct cause of the following exception:

Traceback (most recent call last):
  File "C:\Users\Lenovo\PycharmProjects\光伏功率预测\predict_main.py", line 79, in <module>
    InsertData(table_name='sheet3', data_dict=data_dict)
  File "C:\Users\Lenovo\PycharmProjects\光伏功率预测\sql_lstm.py", line 118, in InsertData
    cursor.execute(sql, data)
  File "E:\conda\envs\pytorch\lib\site-packages\mysql\connector\cursor_cext.py", line 330, in execute
    result = self._cnx.cmd_query(
  File "E:\conda\envs\pytorch\lib\site-packages\mysql\connector\opentelemetry\context_propagation.py", line 77, in wrapper
    return method(cnx, *args, **kwargs)
  File "E:\conda\envs\pytorch\lib\site-packages\mysql\connector\connection_cext.py", line 647, in cmd_query
    raise get_mysql_exception(
mysql.connector.errors.ProgrammingError: 1054 (42S22): Unknown column 'forcast_time' in 'field list'

